Workbook

Sheet Estatisticas_PortugalContinent
A1: Ano | B1: Num_IncendiosRurais | C1: AreaArdPov | D1: AreaArdMato | E1: AreaArdAgric | F1: AreaArdTotal | G1: NIncRur_0_1ha | H1: NIncRur_1_10ha | I1: NIncRur_10_20ha | J1: NIncRur_20_50ha | K1: NIncRur_50_100ha | L1: NIncRur_100_500ha | M1: NIncRur_500_1000ha | N1: NIncRur_1000_n_ha | O1: NInc_Natural | P1: NInc_Negligente | Q1: NInc_Intencionais | R1: NInc_Reacendimentos | S1: NInc_Desconhecida | T1: NInc_NaoInvestigados | U1: Ninc_Sup24h
A2: 2001 | B2: 28915 | C2: 45616.655 | D2: 66638.207 | E2: 5165.5764 | F2: 117420.44 | G2: 21771 | H2: 6147 | I2: 348 | J2: 301 | K2: 163 | L2: 148 | M2: 14 | N2: 23 | O2: 38 | P2: 391 | Q2: 475 | R2: 1159 | S2: 208 | T2: 26644 | U2: 133
A3: 2002 | B3: 28993 | C3: 65164.467 | D3: 59322.722 | E3: 6361.8892 | F3: 130849.08 | G3: 22108 | H3: 5920 | I3: 309 | J3: 262 | K3: 171 | L3: 175 | M3: 30 | N3: 18 | O3: 12 | P3: 414 | Q3: 394 | R3: 1625 | S3: 221 | T3: 26327 | U3: 196
A4: 2003 | B4: 28087 | C4: 286055.47 | D4: 139728.76 | E4: 45965.82 | F4: 471750.05 | G4: 22547 | H4: 4699 | I4: 247 | J4: 199 | K4: 117 | L4: 151 | M4: 45 | N4: 82 | O4: 77 | P4: 522 | Q4: 436 | R4: 1098 | S4: 230 | T4: 25724 | U4: 197
A5: 2004 | B5: 27829 | C5: 56271.465 | D5: 73796.359 | E5: 21302.052 | F5: 151369.88 | G5: 22102 | H5: 4956 | I5: 266 | J5: 216 | K5: 114 | L5: 115 | M5: 28 | N5: 32 | O5: 14 | P5: 421 | Q5: 364 | R5: 1055 | S5: 284 | T5: 25691 | U5: 145
A6: 2005 | B6: 41689 | C6: 213921.29 | D6: 125157.94 | E6: 7638.5914 | F6: 346717.82 | G6: 33005 | H6: 7265 | I6: 407 | J6: 367 | K6: 218 | L6: 284 | M6: 79 | N6: 64 | O6: 3 | P6: 456 | Q6: 619 | R6: 1997 | S6: 377 | T6: 38237 | U6: 511
A7: 2006 | B7: 24243 | C7: 36714.953 | D7: 39769.48 | E7: 7221.4307 | F7: 83705.864 | G7: 20282 | H7: 3375 | I7: 180 | J7: 189 | K7: 84 | L7: 102 | M7: 23 | N7: 8 | O7: 83 | P7: 502 | Q7: 381 | R7: 304 | S7: 1804 | T7: 21169 | U7: 190
A8: 2007 | B8: 25133 | C8: 9819.5738 | D8: 22708.572 | E8: 3884.4019 | F8: 36412.547 | G8: 20964 | H8: 3758 | I8: 180 | J8: 136 | K8: 54 | L8: 35 | M8: 3 | N8: 3 | O8: 63 | P8: 3203 | Q8: 1424 | R8: 565 | S8: 4292 | T8: 15586 | U8: 72
A9: 2008 | B9: 18958 | C9: 5461.3421 | D9: 12009.052 | E9: 2426.8252 | F9: 19897.219 | G9: 15983 | H9: 2703 | I9: 126 | J9: 91 | K9: 35 | L9: 18 | M9: 2 | N9: 0 | O9: 28 | P9: 3490 | Q9: 1570 | R9: 319 | S9: 4367 | T9: 9184 | U9: 139
A10: 2009 | B10: 29783 | C10: 24097.276 | D10: 62724.546 | E10: 5303.8402 | F10: 92125.662 | G10: 23580 | H10: 5328 | I10: 327 | J10: 279 | K10: 133 | L10: 111 | M10: 15 | N10: 10 | O10: 126 | P10: 5190 | Q10: 3540 | R10: 1272 | S10: 4571 | T10: 15084 | U10: 398
A11: 2010 | B11: 26113 | C11: 46053.213 | D11: 86200.837 | E11: 8699.136 | F11: 140953.19 | G11: 21768 | H11: 3521 | I11: 252 | J11: 252 | K11: 129 | L11: 136 | M11: 28 | N11: 27 | O11: 113 | P11: 4161 | Q11: 2845 | R11: 2722 | S11: 6974 | T11: 9298 | U11: 475
A12: 2011 | B12: 29782 | C12: 20036.866 | D12: 52476.649 | E12: 4590.0106 | F12: 77103.526 | G12: 24341 | H12: 4602 | I12: 319 | J12: 267 | K12: 132 | L12: 97 | M12: 18 | N12: 6 | O12: 89 | P12: 7076 | Q12: 3545 | R12: 3736 | S12: 6351 | T12: 8985 | U12: 432
A13: 2012 | B13: 25352 | C13: 48022.79 | D13: 61312.198 | E13: 8649.7945 | F13: 117984.78 | G13: 20626 | H13: 3893 | I13: 300 | J13: 281 | K13: 108 | L13: 117 | M13: 16 | N13: 11 | O13: 58 | P13: 7259 | Q13: 3624 | R13: 2292 | S13: 5826 | T13: 6293 | U13: 38
... A26: 2025 | B26: 8252 | C26: 105076.06 | D26: 139662.03 | E26: 25957.022 | F26: 270695.11 | G26: 6885 | H26: 1015 | I26: 121 | J26: 79 | K26: 51 | L26: 57 | M26: 12 | N26: 32 | O26: 70 | P26: 3142 | Q26: 1965 | R26: 661 | S26: 2399 | T26: 15 | U26: 68

Sheet Estatisticas_Distrito
A1: Ano | B1: Distrito | C1: Num_IncendiosRurais | D1: AreaArdPov_NoDistrito | E1: AreaArdMato_NoDistrito | F1: AreaArdAgric_NoDistrito | G1: AreaArdTotal_NoDistrito | H1: AreaArdPov_IncendioInicioDist | I1: AreaArdMato_IncendioInicioDist | J1: AreaArdAgric_IncendioInicioDist | K1: AreaArdTotal_IncendioInicioDist | L1: NIncRur_0_1ha | M1: NIncRur_1_10ha | N1: NIncRur_10_20ha | O1: NIncRur_20_50ha | P1: NIncRur_50_100ha | Q1: NIncRur_100_500ha | R1: NIncRur_500_1000ha | S1: NIncRur_1000_n_ha | T1: NInc_Natural | U1: NInc_Negligente | V1: NInc_Intencionais | W1: NInc_Reacendimentos | X1: NInc_Desconhecida | Y1: NInc_NaoInvestigados | Z1: Ninc_Sup24h
A2: 2001 | B2: Aveiro | C2: 1987 | D2: (sem informação) | E2: (sem informação) | F2: (sem informação) | G2: (sem informação) | H2: 956.8841 | I2: 605.1465 | J2: 2.8706 | K2: 1564.9012 | L2: 1821 | M2: 146 | N2: 8 | O2: 4 | P2: 5 | Q2: 3 | R2: 0 | S2: 0 | T2: 0 | U2: 15 | V2: 13 | W2: 36 | X2: 6 | Y2: 1917 | Z2: 2
A3: 2001 | B3: Beja | C3: 121 | D3: (sem informação) | E3: (sem informação) | F3: (sem informação) | G3: (sem informação) | H3: 1297.1511 | I3: 640.7519 | J3: 247 | K3: 2184.903 | L3: 41 | M3: 43 | N3: 12 | O3: 12 | P3: 7 | Q3: 6 | R3: 0 | S3: 0 | T3: 0 | U3: 4 | V3: 2 | W3: 1 | X3: 21 | Y3: 93 | Z3: 0
A4: 2001 | B4: Braga | C4: 4245 | D4: (sem informação) | E4: (sem informação) | F4: (sem informação) | G4: (sem informação) | H4: 1815.74 | I4: 3229.14 | J4: 104.37 | K4: 5149.25 | L4: 3241 | M4: 932 | N4: 35 | O4: 24 | P4: 8 | Q4: 5 | R4: 0 | S4: 0 | T4: 0 | U4: 12 | V4: 15 | W4: 2 | X4: 8 | Y4: 4208 | Z4: 6
A5: 2001 | B5: Bragança | C5: 1479 | D5: (sem informação) | E5: (sem informação) | F5: (sem informação) | G5: (sem informação) | H5: 3452.582 | I5: 10540.93 | J5: 857.405 | K5: 14850.917 | L5: 702 | M5: 665 | N5: 26 | O5: 41 | P5: 19 | Q5: 21 | R5: 2 | S5: 3 | T5: 8 | U5: 86 | V5: 22 | W5: 113 | X5: 7 | Y5: 1243 | Z5: 16
A6: 2001 | B6: Castelo Branco | C6: 577 | D6: (sem informação) | E6: (sem informação) | F6: (sem informação) | G6: (sem informação) | H6: 6450.7226 | I6: 5814.4549 | J6: 0 | K6: 12265.178 | L6: 378 | M6: 160 | N6: 5 | O6: 14 | P6: 6 | Q6: 8 | R6: 2 | S6: 4 | T6: 9 | U6: 8 | V6: 8 | W6: 27 | X6: 25 | Y6: 500 | Z6: 19
A7: 2001 | B7: Coimbra | C7: 832 | D7: (sem informação) | E7: (sem informação) | F7: (sem informação) | G7: (sem informação) | H7: 4247.8241 | I7: 3440.0965 | J7: 84.4148 | K7: 7772.3354 | L7: 729 | M7: 88 | N7: 2 | O7: 5 | P7: 3 | Q7: 1 | R7: 1 | S7: 3 | T7: 3 | U7: 55 | V7: 93 | W7: 28 | X7: 20 | Y7: 633 | Z7: 5
A8: 2001 | B8: Évora | C8: 53 | D8: (sem informação) | E8: (sem informação) | F8: (sem informação) | G8: (sem informação) | H8: 1486.5006 | I8: 111.041 | J8: 706.3 | K8: 2303.8416 | L8: 25 | M8: 11 | N8: 3 | O8: 6 | P8: 3 | Q8: 4 | R8: 0 | S8: 1 | T8: 0 | U8: 6 | V8: 1 | W8: 0 | X8: 3 | Y8: 43 | Z8: 0
A9: 2001 | B9: Faro | C9: 215 | D9: (sem informação) | E9: (sem informação) | F9: (sem informação) | G9: (sem informação) | H9: 1632.563 | I9: 1545.735 | J9: 114.976 | K9: 3293.274 | L9: 147 | M9: 54 | N9: 6 | O9: 1 | P9: 2 | Q9: 3 | R9: 0 | S9: 2 | T9: 2 | U9: 0 | V9: 3 | W9: 6 | X9: 12 | Y9: 192 | Z9: 5
A10: 2001 | B10: Guarda | C10: 1744 | D10: (sem informação) | E10: (sem informação) | F10: (sem informação) | G10: (sem informação) | H10: 5725.1236 | I10: 17640.177 | J10: 1524.995 | K10: 24890.296 | L10: 944 | M10: 602 | N10: 58 | O10: 53 | P10: 39 | Q10: 38 | R10: 5 | S10: 5 | T10: 5 | U10: 4 | V10: 13 | W10: 79 | X10: 9 | Y10: 1634 | Z10: 15
A11: 2001 | B11: Leiria | C11: 864 | D11: (sem informação) | E11: (sem informação) | F11: (sem informação) | G11: (sem informação) | H11: 804.3492 | I11: 671.7573 | J11: 41.1122 | K11: 1517.2187 | L11: 732 | M11: 112 | N11: 10 | O11: 3 | P11: 3 | Q11: 4 | R11: 0 | S11: 0 | T11: 0 | U11: 22 | V11: 40 | W11: 39 | X11: 12 | Y11: 751 | Z11: 2
A12: 2001 | B12: Lisboa | C12: 2608 | D12: (sem informação) | E12: (sem informação) | F12: (sem informação) | G12: (sem informação) | H12: 327.2035 | I12: 1024.7882 | J12: 279.1195 | K12: 1631.1112 | L12: 2162 | M12: 432 | N12: 7 | O12: 4 | P12: 2 | Q12: 1 | R12: 0 | S12: 0 | T12: 1 | U12: 5 | V12: 4 | W12: 42 | X12: 4 | Y12: 2552 | Z12: 3
A13: 2001 | B13: Portalegre | C13: 89 | D13: (sem informação) | E13: (sem informação) | F13: (sem informação) | G13: (sem informação) | H13: 2301.2826 | I13: 159.222 | J13: 457.65 | K13: 2918.1546 | L13: 49 | M13: 23 | N13: 4 | O13: 6 | P13: 2 | Q13: 3 | R13: 1 | S13: 1 | T13: 0 | U13: 4 | V13: 0 | W13: 2 | X13: 3 | Y13: 80 | Z13: 0
... A289: 2016 | B289: Viseu | C289: 1134 | D289: (sem informação) | E289: (sem informação) | F289: (sem informação) | G289: (sem informação) | H289: 2176.294 | I289: 8447.6587 | J289: 7.1897 | K289: 10631.142 | L289: 834 | M289: 205 | N289: 31 | O289: 28 | P289: 15 | Q289: 15 | R289: 6 | S289: 0 | T289: 5 | U289: 355 | V289: 310 | W289: 162 | X289: 301 | Y289: 1 | Z289: 16
A290: 2017 | B290: Aveiro | C290: 1661 | D290: 11888.009 | E290: 4306.4634 | F290: 841.0078 | G290: 17035.48 | H290: (sem informação) | I290: (sem informação) | J290: (sem informação) | K290: (sem informação) | L290: 1548 | M290: 85 | N290: 8 | O290: 6 | P290: 3 | Q290: 9 | R290: 0 | S290: 2 | T290: 1 | U290: 205 | V290: 115 | W290: 144 | X290: 1192 | Y290: 4 | Z290: 4
A291: 2017 | B291: Beja | C291: 356 | D291: 1025.8379 | E291: 18.73844 | F291: 1016.0305 | G291: 2060.6068 | H291: (sem informação) | I291: (sem informação) | J291: (sem informação) | K291: (sem informação) | L291: 232 | M291: 88 | N291: 11 | O291: 13 | P291: 8 | Q291: 4 | R291: 0 | S291: 0 | T291: 5 | U291: 154 | V291: 27 | W291: 2 | X291: 168 | Y291: 0 | Z291: 0
A292: 2017 | B292: Braga | C292: 2019 | D292: 5180.3205 | E292: 6325.1449 | F292: 52.06908 | G292: 11557.535 | H292: (sem informação) | I292: (sem informação) | J292: (sem informação) | K292: (sem informação) | L292: 1448 | M292: 448 | N292: 42 | O292: 45 | P292: 15 | Q292: 18 | R292: 0 | S292: 3 | T292: 2 | U292: 363 | V292: 380 | W292: 286 | X292: 617 | Y292: 371 | Z292: 6
A293: 2017 | B293: Bragança | C293: 854 | D293: 2429.6876 | E293: 19880.525 | F293: 1998.1007 | G293: 24308.314 | H293: (sem informação) | I293: (sem informação) | J293: (sem informação) | K293: (sem informação) | L293: 508 | M293: 249 | N293: 38 | O293: 18 | P293: 14 | Q293: 15 | R293: 4 | S293: 8 | T293: 23 | U293: 469 | V293: 93 | W293: 65 | X293: 196 | Y293: 8 | Z293: 6
A294: 2017 | B294: Castelo Branco | C294: 636 | D294: 40469.893 | E294: 17722.173 | F294: 4434.2414 | G294: 62626.307 | H294: (sem informação) | I294: (sem informação) | J294: (sem informação) | K294: (sem informação) | L294: 528 | M294: 71 | N294: 4 | O294: 6 | P294: 6 | Q294: 6 | R294: 4 | S294: 11 | T294: 11 | U294: 264 | V294: 215 | W294: 0 | X294: 142 | Y294: 4 | Z294: 15
A295: 2017 | B295: Coimbra | C295: 741 | D295: 93963.653 | E295: 25749.715 | F295: 6277.0364 | G295: 125990.4 | H295: (sem informação) | I295: (sem informação) | J295: (sem informação) | K295: (sem informação) | L295: 668 | M295: 43 | N295: 6 | O295: 2 | P295: 6 | Q295: 6 | R295: 2 | S295: 8 | T295: 4 | U295: 251 | V295: 312 | W295: 87 | X295: 68 | Y295: 19 | Z295: 14
A296: 2017 | B296: Évora | C296: 285 | D296: 448.8243 | E296: 0.5509 | F296: 1350.7601 | G296: 1800.1353 | H296: (sem informação) | I296: (sem informação) | J296: (sem informação) | K296: (sem informação) | L296: 215 | M296: 51 | N296: 4 | O296: 5 | P296: 4 | Q296: 6 | R296: 0 | S296: 0 | T296: 7 | U296: 99 | V296: 2 | W296: 6 | X296: 171 | Y296: 0 | Z296: 0
A297: 2017 | B297: Faro | C297: 394 | D297: 141.7802 | E297: 114.17027 | F297: 44.057062 | G297: 300.00753 | H297: (sem informação) | I297: (sem informação) | J297: (sem informação) | K297: (sem informação) | L297: 359 | M297: 31 | N297: 2 | O297: 1 | P297: 0 | Q297: 1 | R297: 0 | S297: 0 | T297: 1 | U297: 169 | V297: 33 | W297: 3 | X297: 188 | Y297: 0 | Z297: 0
A298: 2017 | B298: Guarda | C298: 639 | D298: 31059.481 | E298: 32321.086 | F298: 10182.438 | G298: 73563.005 | H298: (sem informação) | I298: (sem informação) | J298: (sem informação) | K298: (sem informação) | L298: 407 | M298: 133 | N298: 22 | O298: 23 | P298: 12 | Q298: 23 | R298: 6 | S298: 13 | T298: 6 | U298: 340 | V298: 115 | W298: 39 | X298: 138 | Y298: 1 | Z298: 14
A299: 2017 | B299: Leiria | C299: 880 | D299: 46359.692 | E299: 1796.8411 | F299: 522.46257 | G299: 48678.995 | H299: (sem informação) | I299: (sem informação) | J299: (sem informação) | K299: (sem informação) | L299: 796 | M299: 64 | N299: 6 | O299: 2 | P299: 2 | Q299: 5 | R299: 0 | S299: 5 | T299: 2 | U299: 138 | V299: 141 | W299: 44 | X299: 548 | Y299: 7 | Z299: 10
A300: 2017 | B300: Lisboa | C300: 1273 | D300: 268.4272 | E300: 1125.3028 | F300: 96.4963 | G300: 1490.2263 | H300: (sem informação) | I300: (sem informação) | J300: (sem informação) | K300: (sem informação) | L300: 1058 | M300: 187 | N300: 13 | O300: 12 | P300: 0 | Q300: 3 | R300: 0 | S300: 0 | T300: 2 | U300: 89 | V300: 6 | W300: 4 | X300: 839 | Y300: 333 | Z300: 2
A301: 2017 | B301: Portalegre | C301: 344 | D301: 6219.6819 | E301: 4646.126 | F301: 2230.1599 | G301: 13095.968 | H301: (sem informação) | I301: (sem informação) | J301: (sem informação) | K301: (sem informação) | L301: 270 | M301: 59 | N301: 5 | O301: 5 | P301: 1 | Q301: 3 | R301: 0 | S301: 1 | T301: 28 | U301: 217 | V301: 44 | W301: 4 | X301: 51 | Y301: 0 | Z301: 0
... A451: 2025 | B451: Viseu | C451: 526 | D451: 16283.739 | E451: 22205.808 | F451: 3586.1078 | G451: 42075.655 | H451: (sem informação) | I451: (sem informação) | J451: (sem informação) | K451: NULL | L451: 428 | M451: 73 | N451: 7 | O451: 3 | P451: 3 | Q451: 6 | R451: 3 | S451: 3 | T451: 3 | U451: 260 | V451: 195 | W451: 38 | X451: 30 | Y451: 0 | Z451: 16

Sheet Estatisticas_NUTS_III
A1: Ano | B1: Região NUTS III (2024) | C1: Num_IncendiosRurais | D1: AreaArdPov_NaNUTS | E1: AreaArdMato_NaNUTS | F1: AreaArdAgric_NaNUTS | G1: AreaArdTotal_NaNUTS | H1: AreaArdPov_IncendioInicioNUTS | I1: AreaArdMato_IncendioInicioNUTS | J1: AreaArdAgric_IncendioInicioNUTS | K1: AreaArdTotal_IncendioInicioNUTS | L1: NIncRur_0_1ha | M1: NIncRur_1_10ha | N1: NIncRur_10_20ha | O1: NIncRur_20_50ha | P1: NIncRur_50_100ha | Q1: NIncRur_100_500ha | R1: NIncRur_500_1000ha | S1: NIncRur_1000_n_ha | T1: NInc_Natural | U1: NInc_Negligente | V1: NInc_Intencionais | W1: NInc_Reacendimentos | X1: NInc_Desconhecida | Y1: NInc_NaoInvestigados | Z1: Ninc_Sup24h
A2: 2001 | B2: Alentejo Central | C2: =SUMIFS(Estatisticas_Concelho!F$2:F$6647,Estatisticas_Concelho!$A$2:$A$6647,$A2,Estatisticas_Concelho!$E$2:$E$6647,$B2) -> 53 | D2: (sem informação) | E2: (sem informação) | F2: (sem informação) | G2: (sem informação) | H2: =SUMIFS(Estatisticas_Concelho!K$2:K$6647,Estatisticas_Concelho!$A$2:$A$6647,$A2,Estatisticas_Concelho!$E$2:$E$6647,$B2) -> 1486.5006 | I2: =SUMIFS(Estatisticas_Concelho!L$2:L$6647,Estatisticas_Concelho!$A$2:$A$6647,$A2,Estatisticas_Concelho!$E$2:$E$6647,$B2) -> 111.041 | J2: =SUMIFS(Estatisticas_Concelho!M$2:M$6647,Estatisticas_Concelho!$A$2:$A$6647,$A2,Estatisticas_Concelho!$E$2:$E$6647,$B2) -> 706.3 | K2: =SUMIFS(Estatisticas_Concelho!N$2:N$6647,Estatisticas_Concelho!$A$2:$A$6647,$A2,Estatisticas_Concelho!$E$2:$E$6647,$B2) -> 2303.8416 | L2: =SUMIFS(Estatisticas_Concelho!O$2:O$6647,Estatisticas_Concelho!$A$2:$A$6647,$A2,Estatisticas_Concelho!$E$2:$E$6647,$B2) -> 25 | M2: =SUMIFS(Estatisticas_Concelho!P$2:P$6647,Estatisticas_Concelho!$A$2:$A$6647,$A2,Estatisticas_Concelho!$E$2:$E$6647,$B2) -> 11 | N2: =SUMIFS(Estatisticas_Concelho!Q$2:Q$6647,Estatisticas_Concelho!$A$2:$A$6647,$A2,Estatisticas_Concelho!$E$2:$E$6647,$B2) -> 3 | O2: =SUMIFS(Estatisticas_Concelho!R$2:R$6647,Estatisticas_Concelho!$A$2:$A$6647,$A2,Estatisticas_Concelho!$E$2:$E$6647,$B2) -> 6 | ... Z2: =SUMIFS(Estatisticas_Concelho!AC$2:AC$6647,Estatisticas_Concelho!$A$2:$A$6647,$A2,Estatisticas_Concelho!$E$2:$E$6647,$B2) -> 0
A3: 2001 | B3: Alentejo Litoral | C3: 138 | D3: (sem informação) | E3: (sem informação) | F3: (sem informação) | G3: (sem informação) | H3: 880.7344 | I3: 48.3933 | J3: 292 | K3: 1221.1277 | L3: 88 | M3: 40 | N3: 1 | O3: 6 | P3: 0 | Q3: 3 | R3: 0 | S3: 0 | T3: 0 | U3: 6 | V3: 3 | W3: 0 | X3: 7 | Y3: 122 | Z3: 1
A4: 2001 | B4: Algarve | C4: 215 | D4: (sem informação) | E4: (sem informação) | F4: (sem informação) | G4: (sem informação) | H4: 1632.563 | I4: 1545.735 | J4: 114.976 | K4: 3293.274 | L4: 147 | M4: 54 | N4: 6 | O4: 1 | P4: 2 | Q4: 3 | R4: 0 | S4: 2 | T4: 2 | U4: 0 | V4: 3 | W4: 6 | X4: 12 | Y4: 192 | Z4: 5
A5: 2001 | B5: Alto Alentejo | C5: 89 | D5: (sem informação) | E5: (sem informação) | F5: (sem informação) | G5: (sem informação) | H5: 2301.2826 | I5: 159.222 | J5: 457.65 | K5: 2918.1546 | L5: 49 | M5: 23 | N5: 4 | O5: 6 | P5: 2 | Q5: 3 | R5: 1 | S5: 1 | T5: 0 | U5: 4 | V5: 0 | W5: 2 | X5: 3 | Y5: 80 | Z5: 0
A6: 2001 | B6: Alto Minho | C6: 1688 | D6: (sem informação) | E6: (sem informação) | F6: (sem informação) | G6: (sem informação) | H6: 2356.5444 | I6: 2220.54 | J6: 23.87131 | K6: 4600.9557 | L6: 1104 | M6: 523 | N6: 25 | O6: 22 | P6: 7 | Q6: 6 | R6: 1 | S6: 0 | T6: 0 | U6: 16 | V6: 18 | W6: 23 | X6: 11 | Y6: 1620 | Z6: 7
A7: 2001 | B7: Alto Tâmega e Barroso | C7: 1176 | D7: (sem informação) | E7: (sem informação) | F7: (sem informação) | G7: (sem informação) | H7: 3030.814 | I7: 6106.015 | J7: 176.76 | K7: 9313.589 | L7: 598 | M7: 469 | N7: 41 | O7: 25 | P7: 23 | Q7: 19 | R7: 0 | S7: 1 | T7: 4 | U7: 72 | V7: 73 | W7: 174 | X7: 39 | Y7: 814 | Z7: 11
A8: 2001 | B8: Área Metropolitana do Porto | C8: 4548 | D8: (sem informação) | E8: (sem informação) | F8: (sem informação) | G8: (sem informação) | H8: 2458.905 | I8: 1240.14 | J8: 10.5 | K8: 3709.545 | L8: 4106 | M8: 392 | N8: 23 | O8: 15 | P8: 7 | Q8: 5 | R8: 0 | S8: 0 | T8: 0 | U8: 4 | V8: 5 | W8: 1 | X8: 1 | Y8: 4537 | Z8: 6
A9: 2001 | B9: Ave | C9: 2917 | D9: (sem informação) | E9: (sem informação) | F9: (sem informação) | G9: (sem informação) | H9: 1081.42 | I9: 2357.895 | J9: 20.06 | K9: 3459.375 | L9: 2238 | M9: 630 | N9: 25 | O9: 16 | P9: 3 | Q9: 5 | R9: 0 | S9: 0 | T9: 0 | U9: 7 | V9: 11 | W9: 2 | X9: 3 | Y9: 2894 | Z9: 2
A10: 2001 | B10: Baixo Alentejo | C10: 86 | D10: (sem informação) | E10: (sem informação) | F10: (sem informação) | G10: (sem informação) | H10: 1236.9005 | I10: 626.7006 | J10: 247 | K10: 2110.6011 | L10: 18 | M10: 32 | N10: 12 | O10: 11 | P10: 7 | Q10: 6 | R10: 0 | S10: 0 | T10: 0 | U10: 4 | V10: 2 | W10: 1 | X10: 17 | Y10: 62 | Z10: 0
A11: 2001 | B11: Beira Baixa | C11: 348 | D11: (sem informação) | E11: (sem informação) | F11: (sem informação) | G11: (sem informação) | H11: 4204.9911 | I11: 1885.8624 | J11: 0 | K11: 6090.8535 | L11: 233 | M11: 94 | N11: 2 | O11: 5 | P11: 5 | Q11: 6 | R11: 1 | S11: 2 | T11: 7 | U11: 4 | V11: 2 | W11: 6 | X11: 14 | Y11: 315 | Z11: 12
A12: 2001 | B12: Beiras e Serra da Estrela | C12: 1845 | D12: (sem informação) | E12: (sem informação) | F12: (sem informação) | G12: (sem informação) | H12: 7697.675 | I12: 20066.499 | J12: 1490.525 | K12: 29254.699 | L12: 1042 | M12: 602 | N12: 58 | O12: 59 | P12: 37 | Q12: 34 | R12: 6 | S12: 7 | T12: 7 | U12: 7 | V12: 19 | W12: 92 | X12: 20 | Y12: 1700 | Z12: 21
A13: 2001 | B13: Cávado | C13: 1150 | D13: (sem informação) | E13: (sem informação) | F13: (sem informação) | G13: (sem informação) | H13: 763.52 | I13: 908.01 | J13: 83.23 | K13: 1754.76 | L13: 866 | M13: 262 | N13: 7 | O13: 9 | P13: 5 | Q13: 1 | R13: 0 | S13: 0 | T13: 0 | U13: 6 | V13: 5 | W13: 0 | X13: 5 | Y13: 1134 | Z13: 4
A14: 2001 | B14: Douro | C14: 2237 | D14: (sem informação) | E14: (sem informação) | F14: (sem informação) | G14: (sem informação) | H14: 2404.025 | I14: 8181.223 | J14: 231.45 | K14: 10816.698 | L14: 1441 | M14: 673 | N14: 39 | O14: 48 | P14: 17 | Q14: 17 | R14: 1 | S14: 1 | T14: 5 | U14: 67 | V14: 51 | W14: 444 | X14: 3 | Y14: 1667 | Z14: 8
... A25: 2001 | B25: Viseu Dão Lafões | C25: 1690 | D25: (sem informação) | E25: (sem informação) | F25: (sem informação) | G25: (sem informação) | H25: 2782.946 | I25: 6766.2722 | J25: 17.1547 | K25: 9566.3729 | L25: 1286 | M25: 350 | N25: 11 | O25: 15 | P25: 13 | Q25: 11 | R25: 1 | S25: 3 | T25: 4 | U25: 26 | V25: 61 | W25: 132 | X25: 16 | Y25: 1451 | Z25: 8
A26: =A2+1 -> 2002 | B26: Alentejo Central | C26: 76 | D26: (sem informação) | E26: (sem informação) | F26: (sem informação) | G26: (sem informação) | H26: 2367.1714 | I26: 473.2117 | J26: 1284.12 | K26: 4124.5031 | L26: 33 | M26: 21 | N26: 5 | O26: 5 | P26: 4 | Q26: 6 | R26: 2 | S26: 0 | T26: 0 | U26: 9 | V26: 0 | W26: 0 | X26: 12 | Y26: 55 | Z26: 3
A27: =A3+1 -> 2002 | B27: Alentejo Litoral | C27: 101 | D27: (sem informação) | E27: (sem informação) | F27: (sem informação) | G27: (sem informação) | H27: 988.2015 | I27: 10.9005 | J27: 86 | K27: 1085.102 | L27: 60 | M27: 32 | N27: 2 | O27: 2 | P27: 3 | Q27: 2 | R27: 0 | S27: 0 | T27: 0 | U27: 6 | V27: 0 | W27: 3 | X27: 11 | Y27: 81 | Z27: 1
A28: =A4+1 -> 2002 | B28: Algarve | C28: 274 | D28: (sem informação) | E28: (sem informação) | F28: (sem informação) | G28: (sem informação) | H28: 567.0113 | I28: 1163.7979 | J28: 102.3325 | K28: 1833.1417 | L28: 196 | M28: 58 | N28: 5 | O28: 6 | P28: 3 | Q28: 6 | R28: 0 | S28: 0 | T28: 0 | U28: 10 | V28: 8 | W28: 22 | X28: 11 | Y28: 223 | Z28: 10
A29: =A5+1 -> 2002 | B29: Alto Alentejo | C29: 75 | D29: (sem informação) | E29: (sem informação) | F29: (sem informação) | G29: (sem informação) | H29: 388.0015 | I29: 303.1014 | J29: 4 | K29: 695.1029 | L29: 38 | M29: 29 | N29: 2 | O29: 3 | P29: 2 | Q29: 1 | R29: 0 | S29: 0 | T29: 0 | U29: 1 | V29: 2 | W29: 0 | X29: 4 | Y29: 68 | Z29: 1
A30: =A6+1 -> 2002 | B30: Alto Minho | C30: 2101 | D30: (sem informação) | E30: (sem informação) | F30: (sem informação) | G30: (sem informação) | H30: 3752.9505 | I30: 6085.3851 | J30: 167.242 | K30: 10005.578 | L30: 1190 | M30: 759 | N30: 79 | O30: 39 | P30: 17 | Q30: 16 | R30: 0 | S30: 1 | T30: 1 | U30: 31 | V30: 26 | W30: 64 | X30: 3 | Y30: 1976 | Z30: 11
A31: =A7+1 -> 2002 | B31: Alto Tâmega e Barroso | C31: 1258 | D31: (sem informação) | E31: (sem informação) | F31: (sem informação) | G31: (sem informação) | H31: 9054.941 | I31: 5551.2101 | J31: 298 | K31: 14904.151 | L31: 727 | M31: 442 | N31: 23 | O31: 27 | P31: 14 | Q31: 20 | R31: 2 | S31: 3 | T31: 3 | U31: 44 | V31: 56 | W31: 230 | X31: 8 | Y31: 917 | Z31: 18
A32: =A8+1 -> 2002 | B32: Área Metropolitana do Porto | C32: 4873 | D32: (sem informação) | E32: (sem informação) | F32: (sem informação) | G32: (sem informação) | H32: 2692.806 | I32: 1180.59 | J32: 18.39 | K32: 3891.786 | L32: 4346 | M32: 482 | N32: 21 | O32: 9 | P32: 10 | Q32: 5 | R32: 0 | S32: 0 | T32: 2 | U32: 5 | V32: 2 | W32: 7 | X32: 0 | Y32: 4857 | Z32: 5
A33: =A9+1 -> 2002 | B33: Ave | C33: 2693 | D33: (sem informação) | E33: (sem informação) | F33: (sem informação) | G33: (sem informação) | H33: 1165.004 | I33: 1908.4065 | J33: 37.94 | K33: 3111.3505 | L33: 2057 | M33: 597 | N33: 18 | O33: 11 | P33: 7 | Q33: 3 | R33: 0 | S33: 0 | T33: 0 | U33: 15 | V33: 18 | W33: 17 | X33: 6 | Y33: 2637 | Z33: 0
A34: =A10+1 -> 2002 | B34: Baixo Alentejo | C34: 81 | D34: (sem informação) | E34: (sem informação) | F34: (sem informação) | G34: (sem informação) | H34: 941.3009 | I34: 371.501 | J34: 802 | K34: 2114.8019 | L34: 28 | M34: 28 | N34: 6 | O34: 9 | P34: 5 | Q34: 5 | R34: 0 | S34: 0 | T34: 0 | U34: 7 | V34: 3 | W34: 2 | X34: 15 | Y34: 54 | Z34: 2
A35: =A11+1 -> 2002 | B35: Beira Baixa | C35: 472 | D35: (sem informação) | E35: (sem informação) | F35: (sem informação) | G35: (sem informação) | H35: 14207.355 | I35: 1844.1823 | J35: 257.0361 | K35: 16308.574 | L35: 322 | M35: 115 | N35: 6 | O35: 5 | P35: 8 | Q35: 10 | R35: 1 | S35: 5 | T35: 0 | U35: 5 | V35: 5 | W35: 35 | X35: 25 | Y35: 402 | Z35: 17
A36: =A12+1 -> 2002 | B36: Beiras e Serra da Estrela | C36: 1560 | D36: (sem informação) | E36: (sem informação) | F36: (sem informação) | G36: (sem informação) | H36: 4273.8084 | I36: 10443.561 | J36: 1122.8803 | K36: 15840.25 | L36: 875 | M36: 555 | N36: 29 | O36: 39 | P36: 28 | Q36: 29 | R36: 3 | S36: 2 | T36: 0 | U36: 70 | V36: 19 | W36: 59 | X36: 39 | Y36: 1373 | Z36: 28
A37: =A13+1 -> 2002 | B37: Cávado | C37: 1248 | D37: (sem informação) | E37: (sem informação) | F37: (sem informação) | G37: (sem informação) | H37: 923.03 | I37: 1007.595 | J37: 20.79 | K37: 1951.415 | L37: 996 | M37: 233 | N37: 10 | O37: 2 | P37: 4 | Q37: 3 | R37: 0 | S37: 0 | T37: 0 | U37: 3 | V37: 6 | W37: 1 | X37: 2 | Y37: 1236 | Z37: 7
... A385: =A361+1 -> 2016 | B385: Viseu Dão Lafões | C385: 574 | D385: (sem informação) | E385: (sem informação) | F385: (sem informação) | G385: (sem informação) | H385: 1322.419 | I385: 2292.031 | J385: 11.0012 | K385: 3625.4512 | L385: 435 | M385: 96 | N385: 16 | O385: 12 | P385: 6 | Q385: 7 | R385: 2 | S385: 0 | T385: 6 | U385: 123 | V385: 134 | W385: 131 | X385: 179 | Y385: 1 | Z385: 5
A386: =A362+1 -> 2017 | B386: Alentejo Central | C386: 285 | D386: 448.8243 | E386: 0.5509 | F386: 1350.7601 | G386: 1800.1353 | H386: (sem informação) | I386: (sem informação) | J386: (sem informação) | K386: (sem informação) | L386: 215 | M386: 51 | N386: 4 | O386: 5 | P386: 4 | Q386: 6 | R386: 0 | S386: 0 | T386: 7 | U386: 99 | V386: 2 | W386: 6 | X386: 171 | Y386: 0 | Z386: 0
A387: =A363+1 -> 2017 | B387: Alentejo Litoral | C387: 172 | D387: 2632.6171 | E387: 44.8087 | F387: 154.2006 | G387: 2831.6264 | H387: (sem informação) | I387: (sem informação) | J387: (sem informação) | K387: (sem informação) | L387: 136 | M387: 27 | N387: 2 | O387: 3 | P387: 3 | Q387: 0 | R387: 0 | S387: 1 | T387: 0 | U387: 68 | V387: 0 | W387: 0 | X387: 104 | Y387: 0 | Z387: 1
A388: =A364+1 -> 2017 | B388: Algarve | C388: 394 | D388: 141.7802 | E388: 114.17027 | F388: 44.057062 | G388: 300.00753 | H388: (sem informação) | I388: (sem informação) | J388: (sem informação) | K388: (sem informação) | L388: 359 | M388: 31 | N388: 2 | O388: 1 | P388: 0 | Q388: 1 | R388: 0 | S388: 0 | T388: 1 | U388: 169 | V388: 33 | W388: 3 | X388: 188 | Y388: 0 | Z388: 0
A389: =A365+1 -> 2017 | B389: Alto Alentejo | C389: 344 | D389: 6219.6819 | E389: 4646.1261 | F389: 2230.1599 | G389: 13095.968 | H389: (sem informação) | I389: (sem informação) | J389: (sem informação) | K389: (sem informação) | L389: 270 | M389: 59 | N389: 5 | O389: 5 | P389: 1 | Q389: 3 | R389: 0 | S389: 1 | T389: 28 | U389: 217 | V389: 44 | W389: 4 | X389: 51 | Y389: 0 | Z389: 0
A390: =A366+1 -> 2017 | B390: Alto Minho | C390: 1163 | D390: 2420.0221 | E390: 6472.0552 | F390: 35.2462 | G390: 8927.3235 | H390: (sem informação) | I390: (sem informação) | J390: (sem informação) | K390: (sem informação) | L390: 857 | M390: 234 | N390: 29 | O390: 24 | P390: 7 | Q390: 9 | R390: 2 | S390: 1 | T390: 0 | U390: 441 | V390: 481 | W390: 214 | X390: 27 | Y390: 0 | Z390: 4
A391: =A367+1 -> 2017 | B391: Alto Tâmega e Barroso | C391: 960 | D391: 2913.8644 | E391: 7433.0811 | F391: 339.4981 | G391: 10686.444 | H391: (sem informação) | I391: (sem informação) | J391: (sem informação) | K391: (sem informação) | L391: 545 | M391: 332 | N391: 33 | O391: 21 | P391: 13 | Q391: 12 | R391: 3 | S391: 1 | T391: 5 | U391: 584 | V391: 264 | W391: 68 | X391: 33 | Y391: 6 | Z391: 9
A392: =A368+1 -> 2017 | B392: Área Metropolitana do Porto | C392: 3003 | D392: 4846.5708 | E392: 2338.2898 | F392: 350.1692 | G392: 7535.0298 | H392: (sem informação) | I392: (sem informação) | J392: (sem informação) | K392: (sem informação) | L392: 2776 | M392: 187 | N392: 12 | O392: 10 | P392: 8 | Q392: 9 | R392: 0 | S392: 1 | T392: 1 | U392: 160 | V392: 31 | W392: 155 | X392: 740 | Y392: 1916 | Z392: 3
A393: =A369+1 -> 2017 | B393: Ave | C393: 1306 | D393: 3240.3552 | E393: 4425.0038 | F393: 25.952 | G393: 7691.311 | H393: (sem informação) | I393: (sem informação) | J393: (sem informação) | K393: (sem informação) | L393: 928 | M393: 293 | N393: 30 | O393: 29 | P393: 13 | Q393: 10 | R393: 0 | S393: 3 | T393: 0 | U393: 228 | V393: 249 | W393: 203 | X393: 313 | Y393: 313 | Z393: 3
A394: =A370+1 -> 2017 | B394: Baixo Alentejo | C394: 300 | D394: 782.6451 | E394: 16.46164 | F394: 951.728 | G394: 1750.8347 | H394: (sem informação) | I394: (sem informação) | J394: (sem informação) | K394: (sem informação) | L394: 190 | M394: 78 | N394: 10 | O394: 13 | P394: 5 | Q394: 4 | R394: 0 | S394: 0 | T394: 5 | U394: 125 | V394: 27 | W394: 2 | X394: 141 | Y394: 0 | Z394: 0
A395: =A371+1 -> 2017 | B395: Beira Baixa | C395: 429 | D395: 35776.523 | E395: 11077.456 | F395: 3548.6212 | G395: 50402.6 | H395: (sem informação) | I395: (sem informação) | J395: (sem informação) | K395: (sem informação) | L395: 350 | M395: 51 | N395: 3 | O395: 4 | P395: 5 | Q395: 5 | R395: 2 | S395: 9 | T395: 11 | U395: 182 | V395: 183 | W395: 0 | X395: 50 | Y395: 3 | Z395: 13
A396: =A372+1 -> 2017 | B396: Beiras e Serra da Estrela | C396: 776 | D396: 35013.6 | E396: 35597.999 | F396: 10444.755 | G396: 81056.354 | H396: (sem informação) | I396: (sem informação) | J396: (sem informação) | K396: (sem informação) | L396: 542 | M396: 142 | N396: 21 | O396: 22 | P396: 10 | Q396: 18 | R396: 7 | S396: 14 | T396: 5 | U396: 393 | V396: 137 | W396: 37 | X396: 202 | Y396: 2 | Z396: 15
A397: =A373+1 -> 2017 | B397: Cávado | C397: 637 | D397: 1425.4093 | E397: 1623.5181 | F397: 20.32008 | G397: 3069.2475 | H397: (sem informação) | I397: (sem informação) | J397: (sem informação) | K397: (sem informação) | L397: 473 | M397: 134 | N397: 10 | O397: 14 | P397: 2 | Q397: 4 | R397: 0 | S397: 0 | T397: 2 | U397: 141 | V397: 82 | W397: 81 | X397: 273 | Y397: 58 | Z397: 3
...

Sheet Estatisticas_Concelho
A1: Ano | B1: DTCC | C1: Distrito | D1: Concelho | E1: Região NUTS III (2024) | F1: Num_IncendiosRurais | G1: AreaArdPov_NoConcelho | H1: AreaArdMato_NoConcelho | I1: AreaArdAgric_NoConcelho | J1: AreaArdTotal_NoConcelho | K1: AreaArdPov_IncendioInicioConc | L1: AreaArdMato_IncendioInicioConc | M1: AreaArdAgric_IncendioInicioConc | N1: AreaArdTotal_IncendioInicioConc | O1: NIncRur_0_1ha | P1: NIncRur_1_10ha | Q1: NIncRur_10_20ha | R1: NIncRur_20_50ha | S1: NIncRur_50_100ha | T1: NIncRur_100_500ha | U1: NIncRur_500_1000ha | V1: NIncRur_1000_n_ha | W1: NInc_Natural | X1: NInc_Negligente | Y1: NInc_Intencionais | Z1: NInc_Reacendimentos | AA1: NInc_Desconhecida | AB1: NInc_NaoInvestigados | AC1: Ninc_Sup24h
A2: 2001 | B2: 101 | C2: Aveiro | D2: Águeda | E2: Região de Aveiro | F2: 84 | G2: (sem informação) | H2: (sem informação) | I2: (sem informação) | J2: (sem informação) | K2: 7.8582 | L2: 2.2464 | M2: 0 | N2: 10.1046 | O2: 83 | P2: 1 | Q2: 0 | R2: 0 | S2: 0 | T2: 0 | U2: 0 | V2: 0 | W2: 0 | X2: 1 | Y2: 0 | Z2: 3 | AA2: 0 | AB2: 80 | AC2: 0
A3: 2001 | B3: 102 | C3: Aveiro | D3: Albergaria-a-Velha | E3: Região de Aveiro | F3: 87 | G3: (sem informação) | H3: (sem informação) | I3: (sem informação) | J3: (sem informação) | K3: 55.8702 | L3: 7.8302 | M3: 0 | N3: 63.7004 | O3: 74 | P3: 11 | Q3: 2 | R3: 0 | S3: 0 | T3: 0 | U3: 0 | V3: 0 | W3: 0 | X3: 0 | Y3: 2 | Z3: 6 | AA3: 0 | AB3: 79 | AC3: 0
A4: 2001 | B4: 103 | C4: Aveiro | D4: Anadia | E4: Região de Aveiro | F4: 65 | G4: (sem informação) | H4: (sem informação) | I4: (sem informação) | J4: (sem informação) | K4: 10.1313 | L4: 1.9012 | M4: 0.035 | N4: 12.0675 | O4: 62 | P4: 3 | Q4: 0 | R4: 0 | S4: 0 | T4: 0 | U4: 0 | V4: 0 | W4: 0 | X4: 1 | Y4: 5 | Z4: 2 | AA4: 0 | AB4: 57 | AC4: 0
A5: 2001 | B5: 104 | C5: Aveiro | D5: Arouca | E5: Área Metropolitana do Porto | F5: 253 | G5: (sem informação) | H5: (sem informação) | I5: (sem informação) | J5: (sem informação) | K5: 564.025 | L5: 374.18 | M5: 0.22 | N5: 938.425 | O5: 203 | P5: 38 | Q5: 3 | R5: 2 | S5: 4 | T5: 3 | U5: 0 | V5: 0 | W5: 0 | X5: 3 | Y5: 1 | Z5: 0 | AA5: 0 | AB5: 249 | AC5: 1
A6: 2001 | B6: 105 | C6: Aveiro | D6: Aveiro | E6: Região de Aveiro | F6: 39 | G6: (sem informação) | H6: (sem informação) | I6: (sem informação) | J6: (sem informação) | K6: 0.071 | L6: 1.4612 | M6: 0.57 | N6: 2.1022 | O6: 39 | P6: 0 | Q6: 0 | R6: 0 | S6: 0 | T6: 0 | U6: 0 | V6: 0 | W6: 0 | X6: 0 | Y6: 0 | Z6: 2 | AA6: 0 | AB6: 37 | AC6: 0
A7: 2001 | B7: 106 | C7: Aveiro | D7: Castelo de Paiva | E7: Tâmega e Sousa | F7: 117 | G7: (sem informação) | H7: (sem informação) | I7: (sem informação) | J7: (sem informação) | K7: 46.11 | L7: 4.73 | M7: 0.09 | N7: 50.93 | O7: 103 | P7: 14 | Q7: 0 | R7: 0 | S7: 0 | T7: 0 | U7: 0 | V7: 0 | W7: 0 | X7: 0 | Y7: 0 | Z7: 0 | AA7: 0 | AB7: 117 | AC7: 1
A8: 2001 | B8: 107 | C8: Aveiro | D8: Espinho | E8: Área Metropolitana do Porto | F8: 120 | G8: (sem informação) | H8: (sem informação) | I8: (sem informação) | J8: (sem informação) | K8: 2.01 | L8: 14.85 | M8: 0.05 | N8: 16.91 | O8: 113 | P8: 7 | Q8: 0 | R8: 0 | S8: 0 | T8: 0 | U8: 0 | V8: 0 | W8: 0 | X8: 0 | Y8: 0 | Z8: 0 | AA8: 0 | AB8: 120 | AC8: 0
A9: 2001 | B9: 108 | C9: Aveiro | D9: Estarreja | E9: Região de Aveiro | F9: 29 | G9: (sem informação) | H9: (sem informação) | I9: (sem informação) | J9: (sem informação) | K9: 1.42 | L9: 0.6384 | M9: 0 | N9: 2.0584 | O9: 29 | P9: 0 | Q9: 0 | R9: 0 | S9: 0 | T9: 0 | U9: 0 | V9: 0 | W9: 0 | X9: 0 | Y9: 0 | Z9: 0 | AA9: 0 | AB9: 29 | AC9: 0
A10: 2001 | B10: 109 | C10: Aveiro | D10: Santa Maria da Feira | E10: Área Metropolitana do Porto | F10: 511 | G10: (sem informação) | H10: (sem informação) | I10: (sem informação) | J10: (sem informação) | K10: 17.7 | L10: 139.16 | M10: 1.1 | N10: 157.96 | O10: 483 | P10: 25 | Q10: 2 | R10: 1 | S10: 0 | T10: 0 | U10: 0 | V10: 0 | W10: 0 | X10: 1 | Y10: 0 | Z10: 0 | AA10: 0 | AB10: 510 | AC10: 0
A11: 2001 | B11: 110 | C11: Aveiro | D11: Ílhavo | E11: Região de Aveiro | F11: 32 | G11: (sem informação) | H11: (sem informação) | I11: (sem informação) | J11: (sem informação) | K11: 0.628 | L11: 0.355 | M11: 0.1395 | N11: 1.1225 | O11: 32 | P11: 0 | Q11: 0 | R11: 0 | S11: 0 | T11: 0 | U11: 0 | V11: 0 | W11: 0 | X11: 0 | Y11: 0 | Z11: 2 | AA11: 1 | AB11: 29 | AC11: 0
A12: 2001 | B12: 111 | C12: Aveiro | D12: Mealhada | E12: Região de Coimbra | F12: 36 | G12: (sem informação) | H12: (sem informação) | I12: (sem informação) | J12: (sem informação) | K12: 3.6351 | L12: 0.465 | M12: 0.1101 | N12: 4.2102 | O12: 35 | P12: 1 | Q12: 0 | R12: 0 | S12: 0 | T12: 0 | U12: 0 | V12: 0 | W12: 0 | X12: 2 | Y12: 2 | Z12: 0 | AA12: 2 | AB12: 30 | AC12: 0
A13: 2001 | B13: 112 | C13: Aveiro | D13: Murtosa | E13: Região de Aveiro | F13: 28 | G13: (sem informação) | H13: (sem informação) | I13: (sem informação) | J13: (sem informação) | K13: 0.885 | L13: 0.53 | M13: 0 | N13: 1.415 | O13: 28 | P13: 0 | Q13: 0 | R13: 0 | S13: 0 | T13: 0 | U13: 0 | V13: 0 | W13: 0 | X13: 1 | Y13: 0 | Z13: 4 | AA13: 0 | AB13: 23 | AC13: 0
... A4421: 2016 | B4421: 1824 | C4421: Viseu | D4421: Vouzela | E4421: Viseu Dão Lafões | F4421: 11 | G4421: (sem informação) | H4421: (sem informação) | I4421: (sem informação) | J4421: (sem informação) | K4421: 1.191 | L4421: 27.506 | M4421: 0.001 | N4421: 28.698 | O4421: 9 | P4421: 1 | Q4421: 0 | R4421: 1 | S4421: 0 | T4421: 0 | U4421: 0 | V4421: 0 | W4421: 1 | X4421: 3 | Y4421: 5 | Z4421: 0 | AA4421: 2 | AB4421: 0 | AC4421: 0
A4422: 2017 | B4422: 101 | C4422: Aveiro | D4422: Águeda | E4422: Região de Aveiro | F4422: 121 | G4422: 352.58088 | H4422: 22.472 | I4422: 4.2487 | J4422: 379.30158 | K4422: (sem informação) | L4422: (sem informação) | M4422: (sem informação) | N4422: (sem informação) | O4422: 111 | P4422: 8 | Q4422: 1 | R4422: 0 | S4422: 0 | T4422: 1 | U4422: 0 | V4422: 0 | W4422: 0 | X4422: 1 | Y4422: 0 | Z4422: 9 | AA4422: 111 | AB4422: 0 | AC4422: 0
A4423: 2017 | B4423: 102 | C4423: Aveiro | D4423: Albergaria-a-Velha | E4423: Região de Aveiro | F4423: 88 | G4423: 25.321 | H4423: 4.896 | I4423: 10.2366 | J4423: 40.4536 | K4423: (sem informação) | L4423: (sem informação) | M4423: (sem informação) | N4423: (sem informação) | O4423: 82 | P4423: 5 | Q4423: 1 | R4423: 0 | S4423: 0 | T4423: 0 | U4423: 0 | V4423: 0 | W4423: 0 | X4423: 0 | Y4423: 0 | Z4423: 5 | AA4423: 83 | AB4423: 0 | AC4423: 0
A4424: 2017 | B4424: 103 | C4424: Aveiro | D4424: Anadia | E4424: Região de Aveiro | F4424: 47 | G4424: 31.0922 | H4424: 22.4929 | I4424: 2.06845 | J4424: 55.65355 | K4424: (sem informação) | L4424: (sem informação) | M4424: (sem informação) | N4424: (sem informação) | O4424: 44 | P4424: 2 | Q4424: 0 | R4424: 1 | S4424: 0 | T4424: 0 | U4424: 0 | V4424: 0 | W4424: 0 | X4424: 17 | Y4424: 0 | Z4424: 8 | AA4424: 22 | AB4424: 0 | AC4424: 0
A4425: 2017 | B4425: 104 | C4425: Aveiro | D4425: Arouca | E4425: Área Metropolitana do Porto | F4425: 120 | G4425: 2920.402 | H4425: 641.1064 | I4425: 293.606 | J4425: 3855.1144 | K4425: (sem informação) | L4425: (sem informação) | M4425: (sem informação) | N4425: (sem informação) | O4425: 101 | P4425: 17 | Q4425: 1 | R4425: 0 | S4425: 0 | T4425: 1 | U4425: 0 | V4425: 0 | W4425: 1 | X4425: 12 | Y4425: 13 | Z4425: 16 | AA4425: 77 | AB4425: 1 | AC4425: 0
A4426: 2017 | B4426: 105 | C4426: Aveiro | D4426: Aveiro | E4426: Região de Aveiro | F4426: 183 | G4426: 1779.9778 | H4426: 2.10278 | I4426: 3.33622 | J4426: 1785.4168 | K4426: (sem informação) | L4426: (sem informação) | M4426: (sem informação) | N4426: (sem informação) | O4426: 169 | P4426: 10 | Q4426: 1 | R4426: 1 | S4426: 0 | T4426: 1 | U4426: 0 | V4426: 1 | W4426: 0 | X4426: 40 | Y4426: 24 | Z4426: 48 | AA4426: 71 | AB4426: 0 | AC4426: 0
A4427: 2017 | B4427: 106 | C4427: Aveiro | D4427: Castelo de Paiva | E4427: Tâmega e Sousa | F4427: 96 | G4427: 3920.9342 | H4427: 864.1049 | I4427: 416.4815 | J4427: 5201.5206 | K4427: (sem informação) | L4427: (sem informação) | M4427: (sem informação) | N4427: (sem informação) | O4427: 85 | P4427: 9 | Q4427: 1 | R4427: 0 | S4427: 0 | T4427: 1 | U4427: 0 | V4427: 0 | W4427: 0 | X4427: 5 | Y4427: 35 | Z4427: 2 | AA4427: 53 | AB4427: 1 | AC4427: 0
A4428: 2017 | B4428: 107 | C4428: Aveiro | D4428: Espinho | E4428: Área Metropolitana do Porto | F4428: 33 | G4428: 0 | H4428: 1.8561 | I4428: 1.7939 | J4428: 3.65 | K4428: (sem informação) | L4428: (sem informação) | M4428: (sem informação) | N4428: (sem informação) | O4428: 33 | P4428: 0 | Q4428: 0 | R4428: 0 | S4428: 0 | T4428: 0 | U4428: 0 | V4428: 0 | W4428: 0 | X4428: 3 | Y4428: 1 | Z4428: 0 | AA4428: 29 | AB4428: 0 | AC4428: 0
A4429: 2017 | B4429: 108 | C4429: Aveiro | D4429: Estarreja | E4429: Região de Aveiro | F4429: 95 | G4429: 3.228 | H4429: 7.438 | I4429: 34.8921 | J4429: 45.5581 | K4429: (sem informação) | L4429: (sem informação) | M4429: (sem informação) | N4429: (sem informação) | O4429: 89 | P4429: 5 | Q4429: 0 | R4429: 1 | S4429: 0 | T4429: 0 | U4429: 0 | V4429: 0 | W4429: 0 | X4429: 15 | Y4429: 23 | Z4429: 1 | AA4429: 56 | AB4429: 0 | AC4429: 0
A4430: 2017 | B4430: 109 | C4430: Aveiro | D4430: Santa Maria da Feira | E4430: Área Metropolitana do Porto | F4430: 280 | G4430: 90.1998 | H4430: 190.7488 | I4430: 0.4837 | J4430: 281.4323 | K4430: (sem informação) | L4430: (sem informação) | M4430: (sem informação) | N4430: (sem informação) | O4430: 266 | P4430: 10 | Q4430: 0 | R4430: 3 | S4430: 1 | T4430: 0 | U4430: 0 | V4430: 0 | W4430: 0 | X4430: 5 | Y4430: 0 | Z4430: 0 | AA4430: 275 | AB4430: 0 | AC4430: 1
A4431: 2017 | B4431: 110 | C4431: Aveiro | D4431: Ílhavo | E4431: Região de Aveiro | F4431: 34 | G4431: 0.3814 | H4431: 0.0125 | I4431: 1.72093 | J4431: 2.11483 | K4431: (sem informação) | L4431: (sem informação) | M4431: (sem informação) | N4431: (sem informação) | O4431: 34 | P4431: 0 | Q4431: 0 | R4431: 0 | S4431: 0 | T4431: 0 | U4431: 0 | V4431: 0 | W4431: 0 | X4431: 22 | Y4431: 3 | Z4431: 1 | AA4431: 8 | AB4431: 0 | AC4431: 0
A4432: 2017 | B4432: 111 | C4432: Aveiro | D4432: Mealhada | E4432: Região de Coimbra | F4432: 46 | G4432: 557.3742 | H4432: 415.8946 | I4432: 1.3296 | J4432: 974.5984 | K4432: (sem informação) | L4432: (sem informação) | M4432: (sem informação) | N4432: (sem informação) | O4432: 44 | P4432: 1 | Q4432: 0 | R4432: 0 | S4432: 0 | T4432: 1 | U4432: 0 | V4432: 0 | W4432: 0 | X4432: 12 | Y4432: 0 | Z4432: 2 | AA4432: 32 | AB4432: 0 | AC4432: 1
A4433: 2017 | B4433: 112 | C4433: Aveiro | D4433: Murtosa | E4433: Região de Aveiro | F4433: 40 | G4433: 0 | H4433: 1.7542 | I4433: 16.2029 | J4433: 17.9571 | K4433: (sem informação) | L4433: (sem informação) | M4433: (sem informação) | N4433: (sem informação) | O4433: 38 | P4433: 1 | Q4433: 1 | R4433: 0 | S4433: 0 | T4433: 0 | U4433: 0 | V4433: 0 | W4433: 0 | X4433: 3 | Y4433: 0 | Z4433: 0 | AA4433: 37 | AB4433: 0 | AC4433: 0
... A6519: 2024 | B6519: 1105 | C6519: Lisboa | D6519: Cascais | E6519: Grande Lisboa | F6519: 10 | G6519: 8.169 | H6519: 63.9336 | I6519: 5.887 | J6519: 77.9896 | K6519: (sem informação) | L6519: (sem informação) | M6519: (sem informação) | N6519: (sem informação) | O6519: 8 | P6519: 1 | Q6519: 0 | R6519: 0 | S6519: 1 | T6519: 0 | U6519: 0 | V6519: 0 | W6519: 0 | X6519: 9 | Y6519: 0 | Z6519: 0 | AA6519: 1 | AB6519: 0 | AC6519: 0
A6520: 2024 | B6520: 1106 | C6520: Lisboa | D6520: Lisboa | E6520: Grande Lisboa | F6520: 0 | G6520: NULL | H6520: NULL | I6520: NULL | J6520: NULL | K6520: (sem informação) | L6520: (sem informação) | M6520: (sem informação) | N6520: (sem informação) | O6520: 0 | P6520: 0 | Q6520: 0 | R6520: 0 | S6520: 0 | T6520: 0 | U6520: 0 | V6520: 0 | W6520: 0 | X6520: 0 | Y6520: 0 | Z6520: 0 | AA6520: 0 | AB6520: 0 | AC6520: 0
A6521: 2024 | B6521: 1107 | C6521: Lisboa | D6521: Loures | E6521: Grande Lisboa | F6521: 11 | G6521: 0.84829197 | H6521: 0.68174135 | I6521: 1.4956577 | J6521: 3.025691 | K6521: (sem informação) | L6521: (sem informação) | M6521: (sem informação) | N6521: (sem informação) | O6521: 10 | P6521: 1 | Q6521: 0 | R6521: 0 | S6521: 0 | T6521: 0 | U6521: 0 | V6521: 0 | W6521: 0 | X6521: 7 | Y6521: 0 | Z6521: 0 | AA6521: 4 | AB6521: 0 | AC6521: 0
A6522: 2024 | B6522: 1108 | C6522: Lisboa | D6522: Lourinhã | E6522: Oeste | F6522: 7 | G6522: 0.0065 | H6522: 0.075 | I6522: 0.02 | J6522: 0.1015 | K6522: (sem informação) | L6522: (sem informação) | M6522: (sem informação) | N6522: (sem informação) | O6522: 7 | P6522: 0 | Q6522: 0 | R6522: 0 | S6522: 0 | T6522: 0 | U6522: 0 | V6522: 0 | W6522: 0 | X6522: 3 | Y6522: 2 | Z6522: 0 | AA6522: 2 | AB6522: 0 | AC6522: 0
A6523: 2024 | B6523: 1109 | C6523: Lisboa | D6523: Mafra | E6523: Grande Lisboa | F6523: 27 | G6523: 13.762569 | H6523: 5.5852045 | I6523: 0.1075 | J6523: 19.455273 | K6523: (sem informação) | L6523: (sem informação) | M6523: (sem informação) | N6523: (sem informação) | O6523: 25 | P6523: 1 | Q6523: 1 | R6523: 0 | S6523: 0 | T6523: 0 | U6523: 0 | V6523: 0 | W6523: 0 | X6523: 16 | Y6523: 0 | Z6523: 2 | AA6523: 8 | AB6523: 1 | AC6523: 0
A6524: 2024 | B6524: 1110 | C6524: Lisboa | D6524: Oeiras | E6524: Grande Lisboa | F6524: 1 | G6524: 0 | H6524: 0.061473229 | I6524: 10.654755 | J6524: 10.716229 | K6524: (sem informação) | L6524: (sem informação) | M6524: (sem informação) | N6524: (sem informação) | O6524: 0 | P6524: 0 | Q6524: 1 | R6524: 0 | S6524: 0 | T6524: 0 | U6524: 0 | V6524: 0 | W6524: 0 | X6524: 0 | Y6524: 0 | Z6524: 0 | AA6524: 1 | AB6524: 0 | AC6524: 0
A6525: 2024 | B6525: 1111 | C6525: Lisboa | D6525: Sintra | E6525: Grande Lisboa | F6525: 37 | G6525: 0.21909627 | H6525: 7.4866687 | I6525: 1.9778852 | J6525: 9.6836501 | K6525: (sem informação) | L6525: (sem informação) | M6525: (sem informação) | N6525: (sem informação) | O6525: 34 | P6525: 3 | Q6525: 0 | R6525: 0 | S6525: 0 | T6525: 0 | U6525: 0 | V6525: 0 | W6525: 0 | X6525: 26 | Y6525: 1 | Z6525: 2 | AA6525: 8 | AB6525: 0 | AC6525: 0
A6526: 2024 | B6526: 1112 | C6526: Lisboa | D6526: Sobral de Monte Agraço | E6526: Oeste | F6526: 3 | G6526: 0.89235524 | H6526: 1.5530104 | I6526: 0.096192495 | J6526: 2.5415581 | K6526: (sem informação) | L6526: (sem informação) | M6526: (sem informação) | N6526: (sem informação) | O6526: 2 | P6526: 1 | Q6526: 0 | R6526: 0 | S6526: 0 | T6526: 0 | U6526: 0 | V6526: 0 | W6526: 0 | X6526: 2 | Y6526: 1 | Z6526: 0 | AA6526: 0 | AB6526: 0 | AC6526: 0
A6527: 2024 | B6527: 1113 | C6527: Lisboa | D6527: Torres Vedras | E6527: Oeste | F6527: 27 | G6527: 0.47586989 | H6527: 2.8177158 | I6527: 1.4346676 | J6527: 4.7282533 | K6527: (sem informação) | L6527: (sem informação) | M6527: (sem informação) | N6527: (sem informação) | O6527: 25 | P6527: 2 | Q6527: 0 | R6527: 0 | S6527: 0 | T6527: 0 | U6527: 0 | V6527: 0 | W6527: 0 | X6527: 11 | Y6527: 13 | Z6527: 0 | AA6527: 3 | AB6527: 0 | AC6527: 0
A6528: 2024 | B6528: 1114 | C6528: Lisboa | D6528: Vila Franca de Xira | E6528: Grande Lisboa | F6528: 7 | G6528: 0.0027886354 | H6528: 2.560037 | I6528: 1.2 | J6528: 3.7628256 | K6528: (sem informação) | L6528: (sem informação) | M6528: (sem informação) | N6528: (sem informação) | O6528: 5 | P6528: 2 | Q6528: 0 | R6528: 0 | S6528: 0 | T6528: 0 | U6528: 0 | V6528: 0 | W6528: 0 | X6528: 7 | Y6528: 0 | Z6528: 0 | AA6528: 0 | AB6528: 0 | AC6528: 0
A6529: 2024 | B6529: 1115 | C6529: Lisboa | D6529: Amadora | E6529: Grande Lisboa | F6529: 1 | G6529: 0 | H6529: 0.665 | I6529: 0 | J6529: 0.665 | K6529: (sem informação) | L6529: (sem informação) | M6529: (sem informação) | N6529: (sem informação) | O6529: 1 | P6529: 0 | Q6529: 0 | R6529: 0 | S6529: 0 | T6529: 0 | U6529: 0 | V6529: 0 | W6529: 0 | X6529: 1 | Y6529: 0 | Z6529: 0 | AA6529: 0 | AB6529: 0 | AC6529: 0
A6530: 2024 | B6530: 1116 | C6530: Lisboa | D6530: Odivelas | E6530: Grande Lisboa | F6530: 4 | G6530: 0 | H6530: 0.51245051 | I6530: 0.0217 | J6530: 0.53415051 | K6530: (sem informação) | L6530: (sem informação) | M6530: (sem informação) | N6530: (sem informação) | O6530: 4 | P6530: 0 | Q6530: 0 | R6530: 0 | S6530: 0 | T6530: 0 | U6530: 0 | V6530: 0 | W6530: 0 | X6530: 3 | Y6530: 0 | Z6530: 0 | AA6530: 1 | AB6530: 0 | AC6530: 0
A6531: 2024 | B6531: 1201 | C6531: Portalegre | D6531: Alter do Chão | E6531: Alto Alentejo | F6531: 3 | G6531: 0 | H6531: 0 | I6531: 0.16594 | J6531: 0.16594 | K6531: (sem informação) | L6531: (sem informação) | M6531: (sem informação) | N6531: (sem informação) | O6531: 3 | P6531: 0 | Q6531: 0 | R6531: 0 | S6531: 0 | T6531: 0 | U6531: 0 | V6531: 0 | W6531: 0 | X6531: 1 | Y6531: 0 | Z6531: 0 | AA6531: 2 | AB6531: 0 | AC6531: 0
A6532: 2024 | B6532: 1202 | C6532: Portalegre | D6532: Arronches | E6532: Alto Alentejo | F6532: 5 | G6532: 0 | H6532: 0.4604 | I6532: 0.1364 | J6532: 0.5968 | K6532: (sem informação) | L6532: (sem informação) | M6532: (sem informação) | N6532: (sem informação) | O6532: 5 | P6532: 0 | Q6532: 0 | R6532: 0 | S6532: 0 | T6532: 0 | U6532: 0 | V6532: 0 | W6532: 0 | X6532: 2 | Y6532: 0 | Z6532: 0 | AA6532: 3 | AB6532: 0 | AC6532: 0
...

Sheet Legendas
A1: LEGENDAS
A2: Tabela | B2: Estatisticas_PortugalContinental
A3: Campo | B3: Descrição
A4: Num_IncendiosRurais | B4: Número de incêndios rurais
A5: AreaArdPov | B5: Área ardidade povoamentos florestais, em hectares
A6: AreaArdMato | B6: Área ardidade matos, em hectares
A7: AreaArdAgric | B7: Área ardidade agricultura, em hectares
A8: AreaArdTotal | B8: Área ardidatotal, em hectares
A9: NIncRur_0_1ha | B9: Número de incêndios rurais com área ardida total entre ]0 e 1[ ha
A10: NIncRur_1_10ha | B10: Número de incêndios rurais com área ardida total entre [1 e 10[ ha
A11: NIncRur_10_20ha | B11: Número de incêndios rurais com área ardida total entre [10 e 20[ ha
A12: NIncRur_20_50ha | B12: Número de incêndios rurais com área ardida total entre [20 e 50[ ha
A13: NIncRur_50_100ha | B13: Número de incêndios rurais com área ardida total entre [50 e 100[ ha
... A106: Ninc_Sup24h | B106: Número de incêndios rurais com duração superior a 24 horas (período entre a data/hora de alerta e a data/hora de extinção)

Sheet SQL
B1: PORTUGAL CONTINENTAL | C1: DISTRITOS | D1: NUTS3 | E1: CONCELHOS
A2: Lista Incendios Rurais | B2: USE SGIF SELECT Ano, Codigo, Distrito, Concelho, Freguesia, [Local], INE as DTCCFR, cast(DataAlerta as DATE) as DataAlerta, HoraAlerta, cast(Data1Intervencao as DATE) as Data1Intervencao, Hora1Intervencao, cast(DataExtincao as DATE) as DataExtincao, HoraExtincao, round(cast(datediff(second, cast(DataAlerta + HoraAlerta as datetime), cast(DataExtincao + HoraExtincao as datetime))/3600.0 as float),1) as DuracaoHoras, AreaPov, AreaMato, AreaAgric, AreaPov + AreaMato + AreaAgric as AreaTotal, APS, FonteAlerta, Causa, x_3763 as X_ETRS89, y_3763 as Y_ETRS89, x as X_CoordMilitar, y as Y_CoordMilitar, lat as Lat_GMS, case when left(lon,1)<>'-' then '-' + lon else lon end as Lon_GMS, dbo.fazdecimal(lat) as Lat_Decimal, -1*abs(dbo.fazdecimal(lon)) as Lon_Decimal, case when cast(datediff(second, cast(DataAlerta + HoraAlerta as datetime), cast(DataExtincao + HoraExtincao as datetime))/3600.0 as float) > 24.0 then 1 else 0 end as In_cSup24h FROM dbo.Stat_MasterT Where (fogacho=1 or incendio=1 or agricola=1 ) and (Ano between 2001 and 2019) -- and codigo in ('TM213444', 'TM213445') Order by dataalerta | C2: Select s.Ano, s.Codigo, s.NCCO, DSR, FWI, FFMC, DMC, DC, ISI, BUI from stat_master_meteo m inner join stat_mastert s on s.codigo=m.codigo where s.ano between 2001 and 2019 and (s.incendio=1 or s.fogacho=1 or s.agricola=1) | D2: USE SGIF SELECT Codigo as Codigo_SGIF, CodigoSado as Codigo_ANEPC ,Ano, Mes, Dia, Hora ,AreaPov, AreaMato, AreaAgric, AreaTotal ,case when AreaTotal <1 then ']0 a 1 ha[' when AreaTotal <10 then '[1 a 10 ha]' when AreaTotal <20 then '[10 a 20 ha]' when AreaTotal <50 then '[20 a 50 ha]' when AreaTotal <100 then '[50 a 100 ha]' when AreaTotal <500 then '[100 a 500 ha]' when AreaTotal <1000 then '[500 a 1000 ha]' when AreaTotal >=1000 then '[superior a 1000 ha]' end as ClasseArea ,DHInicio as DataHoraAlerta, DH1Intervencao DataHora_PrimeiraIntervencao, DHFim as DataHora_Extincao, Duracao as Duracao_Horas, Case when duracao>= 24 then 1 else 0 end as IncSup24horas ,INE as DTCCFR, Distrito, Concelho, Freguesia, Local ,APS as RNAP,Perimetro as RNMPF ,x_20790 as X_Militar, y_20790 as Y_Militar, Lat_4326 as Latitude, Lon_4326 as Longitude, x_3763 as X_ETRS89, y_3763 as Y_ETRS89 ,DSR, FWI, ISI, DC, DMC, FFMC, BUI ,Causa as CodCausa, TipoCausa, GrupoCausa, Descricao as DescricaoCausa ,FonteAlerta FROM SGIF.dbo.Stat_MasterT_Export WHERE ano between 2001 and 2010 ORDER BY dhinicio
A3: Estatisticas agregadas | B3: USE SGIF Select Ano, SUM(NIncendios+NFogachos+NAgricola) as Num_IncendiosRurais, Sum(AreaPov) as AreaArdPov, Sum(AreaMato) as AreaArdMato, Sum(AreaAgric) as AreaArdAgric, Sum(AreaTotal) as AreaArdTotal, SUM(NIncRur_0_1ha) as NIncRur_0_1ha, SUM(NIncRur_1_10ha) as NIncRur_1_10ha, SUM(NIncRur_10_20ha) as NIncRur_10_20ha, SUM(NIncRur_20_50ha) as NIncRur_20_50ha, SUM(NIncRur_50_100ha) as NIncRur_50_100ha, SUM(NIncRur_100_500ha) as NIncRur_100_500ha, SUM(NIncRur_500_1000ha) as NIncRur_500_1000ha, SUM(NIncRur_1000_n_ha) as NIncRur_1000_n_ha, SUM(NNatural) as NInc_Natural, SUM(NNegligente) as NInc_Negligente, SUM(NIntenconais) as NInc_Intencionais, SUM(NReacendimentos) as NInc_Reacendimentos, SUM(NDesconhecida) as NInc_Desconhecida, SUM(NIncendios+NFogachos+NAgricola-NNatural-NNegligente-NIntenconais-NReacendimentos-NDesconhecida) as NInc_NaoInvestigados, isnull(NumInc_Sup24h,0) as NumInc_Sup24h From RELATORIO_Stat_Concelho_EntreDatasIII_2023 LEFT JOIN (Select ano as ano24h, count(*) as NumInc_Sup24h from Stat_MasterT where Duracao>=24*60 and (incendio=1 or fogacho=1 or agricola=1) group by ano) t24 on ano = ano24h Where Ano between 2021 and 2021 Group by Ano, NumInc_Sup24h Order by Ano | C3: USE SGIF Select Ano, Distrito, SUM(NIncendios+NFogachos+NAgricola) as Num_IncendiosRurais, Case when ano>=2017 then Sum(AreaPov) end as AreaArdPov_NoDistrito, Case when ano>=2017 then Sum(AreaMato) end as AreaArdMato_NoDistrito, Case when ano>=2017 then Sum(AreaAgric) end as AreaArdAgric_NoDistrito, Case when ano>=2017 then Sum(AreaTotal) end as AreaArdTotal_NoDistrito, Case when ano<2017 then Sum(AreaPov) end as AreaArdPov_IncendioInicioDist, Case when ano<2017 then Sum(AreaMato) end as AreaArdMato_IncendioInicioDist, Case when ano<2017 then Sum(AreaAgric) end as AreaArdAgric_IncendioInicioDist, Case when ano<2017 then Sum(AreaTotal) end as AreaArdTotal_IncendioInicioDist, SUM(NIncRur_0_1ha) as NIncRur_0_1ha, SUM(NIncRur_1_10ha) as NIncRur_1_10ha, SUM(NIncRur_10_20ha) as NIncRur_10_20ha, SUM(NIncRur_20_50ha) as NIncRur_20_50ha, SUM(NIncRur_50_100ha) as NIncRur_50_100ha, SUM(NIncRur_100_500ha) as NIncRur_100_500ha, SUM(NIncRur_500_1000ha) as NIncRur_500_1000ha, SUM(NIncRur_1000_n_ha) as NIncRur_1000_n_ha, SUM(NNatural) as NInc_Natural, SUM(NNegligente) as NInc_Negligente, SUM(NIntenconais) as NInc_Intencionais, SUM(NReacendimentos) as NInc_Reacendimentos, SUM(NDesconhecida) as NInc_Desconhecida, SUM(NIncendios+NFogachos+NAgricola-NNatural-NNegligente-NIntenconais-NReacendimentos-NDesconhecida) as NInc_NaoInvestigados, isnull(NumInc_Sup24h,0) as NumInc_Sup24h From RELATORIO_Stat_Concelho_EntreDatasIII_2023 LEFT JOIN (Select distrito as Distrito24h, ano as ano24h, count(*) as NumInc_Sup24h from Stat_MasterT where Duracao>=24*60 and (incendio=1 or fogacho=1 or agricola=1)group by distrito, ano) t24 on ano = ano24h and distrito = distrito24h COLLATE DATABASE_DEFAULT Where Ano between 2025 and 2025 Group by Ano, cast(DTCC/100 as int), Distrito, Distrito24h, ano24h, NumInc_Sup24h Order by Ano, cast(DTCC/100 as int) | D3: USE SGIF Select Ano, NUTS3, SUM(NIncendios+NFogachos+NAgricola) as Num_IncendiosRurais, Case when ano>=2017 then Sum(AreaPov) end as AreaArdPov_NoConcelho, Case when ano>=2017 then Sum(AreaMato) end as AreaArdMato_NoConcelho, Case when ano>=2017 then Sum(AreaAgric) end as AreaArdAgric_NoConcelho, Case when ano>=2017 then Sum(AreaTotal) end as AreaArdTotal_NoConcelho, Case when ano<2017 then Sum(AreaPov) end as AreaArdPov_IncendioInicioConc, Case when ano<2017 then Sum(AreaMato) end as AreaArdMato_IncendioInicioConc, Case when ano<2017 then Sum(AreaAgric) end as AreaArdAgric_IncendioInicioConc, Case when ano<2017 then Sum(AreaTotal) end as AreaArdTotal_IncendioInicioConc, SUM(NIncRur_0_1ha) as NIncRur_0_1ha, SUM(NIncRur_1_10ha) as NIncRur_1_10ha, SUM(NIncRur_10_20ha) as NIncRur_10_20ha, SUM(NIncRur_20_50ha) as NIncRur_20_50ha, SUM(NIncRur_50_100ha) as NIncRur_50_100ha, SUM(NIncRur_100_500ha) as NIncRur_100_500ha, SUM(NIncRur_500_1000ha) as NIncRur_500_1000ha, SUM(NIncRur_1000_n_ha) as NIncRur_1000_n_ha, SUM(NNatural) as NInc_Natural, SUM(NNegligente) as NInc_Negligente, SUM(NIntenconais) as NInc_Intencionais, SUM(NReacendimentos) as NInc_Reacendimentos, SUM(NDesconhecida) as NInc_Desconhecida, SUM(NIncendios+NFogachos+NAgricola-NNatural-NNegligente-NIntenconais-NReacendimentos-NDesconhecida) as NInc_NaoInvestigados, isnull(NumInc_Sup24h,0) as NumInc_Sup24h From RELATORIO_Stat_Concelho_EntreDatasIII_2023 LEFT JOIN (Select NUTS3_pos2023 as Nuts324h, ano as ano24h, count(*) as NumInc_Sup24h from Stat_MasterT where Duracao>=24*60 and (incendio=1 or fogacho=1 or agricola=1) group by NUTS3_pos2023, ano) t24 on ano = ano24h and NUTS3 = Nuts324h COLLATE DATABASE_DEFAULT Where Ano between 2025 and 2025 -- and concelho = 'Vila de Rei' Group by Ano, NUTS3, Nuts324h, ano24h, NumInc_Sup24h, NUTS3 Order by Ano | E3: USE SGIF Select Ano, DTCC, Distrito, Concelho, NUTS3, SUM(NIncendios+NFogachos+NAgricola) as Num_IncendiosRurais, Case when ano>=2017 then Sum(AreaPov) end as AreaArdPov_NoConcelho, Case when ano>=2017 then Sum(AreaMato) end as AreaArdMato_NoConcelho, Case when ano>=2017 then Sum(AreaAgric) end as AreaArdAgric_NoConcelho, Case when ano>=2017 then Sum(AreaTotal) end as AreaArdTotal_NoConcelho, Case when ano<2017 then Sum(AreaPov) end as AreaArdPov_IncendioInicioConc, Case when ano<2017 then Sum(AreaMato) end as AreaArdMato_IncendioInicioConc, Case when ano<2017 then Sum(AreaAgric) end as AreaArdAgric_IncendioInicioConc, Case when ano<2017 then Sum(AreaTotal) end as AreaArdTotal_IncendioInicioConc, SUM(NIncRur_0_1ha) as NIncRur_0_1ha, SUM(NIncRur_1_10ha) as NIncRur_1_10ha, SUM(NIncRur_10_20ha) as NIncRur_10_20ha, SUM(NIncRur_20_50ha) as NIncRur_20_50ha, SUM(NIncRur_50_100ha) as NIncRur_50_100ha, SUM(NIncRur_100_500ha) as NIncRur_100_500ha, SUM(NIncRur_500_1000ha) as NIncRur_500_1000ha, SUM(NIncRur_1000_n_ha) as NIncRur_1000_n_ha, SUM(NNatural) as NInc_Natural, SUM(NNegligente) as NInc_Negligente, SUM(NIntenconais) as NInc_Intencionais, SUM(NReacendimentos) as NInc_Reacendimentos, SUM(NDesconhecida) as NInc_Desconhecida, SUM(NIncendios+NFogachos+NAgricola-NNatural-NNegligente-NIntenconais-NReacendimentos-NDesconhecida) as NInc_NaoInvestigados, isnull(NumInc_Sup24h,0) as NumInc_Sup24h From RELATORIO_Stat_Concelho_EntreDatasIII_2023 LEFT JOIN (Select concelho as Concelho24h, ano as ano24h, count(*) as NumInc_Sup24h from Stat_MasterT where Duracao>=24*60 and (incendio=1 or fogacho=1 or agricola=1) group by concelho, ano) t24 on ano = ano24h and concelho = concelho24h COLLATE DATABASE_DEFAULT Where Ano between 2023 and 2023 -- and concelho = 'Vila de Rei' Group by Ano, DTCC, Distrito, Concelho, Concelho24h, ano24h, NumInc_Sup24h, NUTS3 Order by Ano, DTCC
A4: APS | B4: USE SGIF Select Ano, Classif as Tipo_AP, Nome, COUNT(*) as Num_IncendiosRurais, SUM(Case when areatotal < 1 THEN 1 ELSE 0 END) AS NIncRurAPS_0_1ha, SUM(Case when areatotal >=1 and areatotal < 5 THEN 1 ELSE 0 END) AS NIncRurAPS_1_5ha, SUM(Case when areatotal >=5 and areatotal < 20 THEN 1 ELSE 0 END) AS NIncRurAPS_5_20ha, SUM(Case when areatotal >=20 and areatotal<100 THEN 1 ELSE 0 END) AS NIncRurAPS_20_100ha, SUM(Case when areatotal >=100 THEN 1 ELSE 0 END) AS NIncRurAPS_100_n_ha From Stat_MasterT left join afn_geografia.dbo.AP2013 ap on aps=ap.nome COLLATE SQL_Latin1_General_CP1_CI_AS Where (Incendio=1 or Fogacho=1 or Agricola=1) and APS is not null -- and Ano = 2016 Group by Ano, Nome, Classif Order by Ano, Classif
